Workbook

Sheet RawData
A1: unique_id | B1: first_name | C1: last_name | D1: sex | E1: country | F1: city | G1: phone_number | H1: email | I1: sign_contract_date_raw | J1: gb_downloaded | K1: gb_uploaded | L1: loyalty_points | M1: monthly_fee | N1: discount_percent | O1: monthly_revenue | P1: plan_name | Q1: discount_category | R1: customer_segment | S1: Sign-up Month
A2: DxSAVy | B2: Amanda | C2: Rivera | D2: Female | E2: Brazil | F2: Porto Alegre | G2: +55209999391 | H2: amanda.rivera74@yahoo.com | I2: 84.336319 | J2: 753.9 | K2: 173.01 | M2: {=_xlfn.XLOOKUP(A2,subscriptions!B2:B10004,subscriptions!D2:D10004)} -> 120 | N2: {=_xlfn.XLOOKUP(A2,subscriptions!B2:B10004,subscriptions!G2:G10004)} -> 5 | O2: {=M2:M10004 * (1-(N2:N10004/100))} -> 114 | P2: {=_xlfn.XLOOKUP(A2,subscriptions!B2:B10004,subscriptions!C2:C10004)} -> Residential | Q2: {=IF(N2:N10004=0,"No discount",IF((N2:N10004>0)*(N2:N10004<10),"Small discount",IF(N2:N10004>=10,"Large discount"," ")))} -> Small discount | R2: {=IF(O2:O10004="","",IF(O2:O10004<100,"Low Value",IF(O2:O10004<200,"Medium Value","High Value")))} -> Medium Value | S2: {=IF(I2:I10004="","",LEFT(I2:I10004,7))} -> 2024:04
A3: 5NXFhm | B3: Cynthia | C3: Taylor | D3: Female | E3: United Kingdom | F3: Edinburgh | G3: +44184843343 | H3: cynthia.taylor60@yahoo.com | I3: 84.256528 | J3: 4565.18 | K3: 670.46 | M3: {=_xlfn.XLOOKUP(A3,subscriptions!B3:B10004,subscriptions!D3:D10004)} -> 250 | N3: {=_xlfn.XLOOKUP(A3,subscriptions!B3:B10004,subscriptions!G3:G10004)} -> 10 | O3: 225 | P3: {=_xlfn.XLOOKUP(A3,subscriptions!B3:B10004,subscriptions!C3:C10004)} -> Business | Q3: Large discount | R3: High Value | S3: 2022:09
A4: x2uJPT | B4: Jessica | C4: Lewis | D4: Female | E4: United Kingdom | F4: Birmingham | G4: +44054556925 | H4: jessica.lewis62@yahoo.com | I4: 84.255058 | J4: 2025.12 | K4: 274.76 | M4: {=_xlfn.XLOOKUP(A4,subscriptions!B4:B10004,subscriptions!D4:D10004)} -> 50 | N4: {=_xlfn.XLOOKUP(A4,subscriptions!B4:B10004,subscriptions!G4:G10004)} -> 20 | O4: 40 | P4: {=_xlfn.XLOOKUP(A4,subscriptions!B4:B10004,subscriptions!C4:C10004)} -> Mini | Q4: Large discount | R4: Low Value | S4: 2022:07
A5: tB7Ut2 | B5: Santiago | C5: Lee | D5: Male | E5: United Kingdom | F5: Manchester | G5: +44472474607 | H5: santiago.lee38@proton.me | I5: 84.257049 | J5: 1419.41 | K5: 232.56 | M5: {=_xlfn.XLOOKUP(A5,subscriptions!B5:B10004,subscriptions!D5:D10004)} -> 50 | N5: {=_xlfn.XLOOKUP(A5,subscriptions!B5:B10004,subscriptions!G5:G10004)} -> 0 | O5: 50 | P5: {=_xlfn.XLOOKUP(A5,subscriptions!B5:B10004,subscriptions!C5:C10004)} -> Mini | Q5: No discount | R5: Low Value | S5: 2022:10
A6: i4A2yx | B6: Michael | C6: Walker | D6: Male | E6: Ukraine | F6: Lviv | G6: +380470273298 | H6: michael.walker22@hotmail.com | I6: 84.334306 | J6: 304.44 | K6: 85 | L6: 100 | M6: {=_xlfn.XLOOKUP(A6,subscriptions!B6:B10004,subscriptions!D6:D10004)} -> 50 | N6: {=_xlfn.XLOOKUP(A6,subscriptions!B6:B10004,subscriptions!G6:G10004)} -> 5 | O6: 47.5 | P6: {=_xlfn.XLOOKUP(A6,subscriptions!B6:B10004,subscriptions!C6:C10004)} -> Mini | Q6: Small discount | R6: Low Value | S6: 2024:01
A7: u27pCF | B7: Ronald | C7: Miller | D7: Male | E7: Ukraine | F7: Donetsk | G7: +380358396343 | H7: ronald.miller64@zoho.com | I7: 84.169618 | J7: 304.39 | K7: 43.66 | L7: 100 | M7: {=_xlfn.XLOOKUP(A7,subscriptions!B7:B10004,subscriptions!D7:D10004)} -> 120 | N7: {=_xlfn.XLOOKUP(A7,subscriptions!B7:B10004,subscriptions!G7:G10004)} -> 10 | O7: 108 | P7: {=_xlfn.XLOOKUP(A7,subscriptions!B7:B10004,subscriptions!C7:C10004)} -> Residential | Q7: Large discount | R7: Medium Value | S7: 2020:04
A8: SylVYM | B8: Christopher | C8: Jackson | D8: Male | E8: Canada | F8: Hamilton | G8: +1741066023 | H8: christopher.jackson53@hotmail.com | I8: 84.339711 | J8: 139.76 | K8: 42.04 | M8: {=_xlfn.XLOOKUP(A8,subscriptions!B8:B10004,subscriptions!D8:D10004)} -> 80 | N8: {=_xlfn.XLOOKUP(A8,subscriptions!B8:B10004,subscriptions!G8:G10004)} -> 20 | O8: 64 | P8: {=_xlfn.XLOOKUP(A8,subscriptions!B8:B10004,subscriptions!C8:C10004)} -> Roam | Q8: Large discount | R8: Low Value | S8: 2024:09
A9: Pdbbe3 | B9: Edward | C9: Baker | D9: Male | E9: United States | F9: San Diego | G9: +1944171340 | H9: edward.baker43@hotmail.com | I9: 84.341042 | J9: 3066.85 | K9: 474.23 | M9: {=_xlfn.XLOOKUP(A9,subscriptions!B9:B10004,subscriptions!D9:D10004)} -> 120 | N9: {=_xlfn.XLOOKUP(A9,subscriptions!B9:B10004,subscriptions!G9:G10004)} -> 0 | O9: 120 | P9: {=_xlfn.XLOOKUP(A9,subscriptions!B9:B10004,subscriptions!C9:C10004)} -> Residential | Q9: No discount | R9: Medium Value | S9: 2024:11
A10: ZLANQw | B10: Jessica | C10: Clark | D10: Female | E10: Germany | F10: Berlin | G10: +49811771185 | H10: jessica.clark42@zoho.com | I10: 84.298854 | J10: 1428.62 | K10: 295.99 | M10: {=_xlfn.XLOOKUP(A10,subscriptions!B10:B10004,subscriptions!D10:D10004)} -> 120 | N10: {=_xlfn.XLOOKUP(A10,subscriptions!B10:B10004,subscriptions!G10:G10004)} -> 5 | O10: 114 | P10: {=_xlfn.XLOOKUP(A10,subscriptions!B10:B10004,subscriptions!C10:C10004)} -> Residential | Q10: Small discount | R10: Medium Value | S10: 2023:10
A11: yjbWTZ | B11: Sophia | C11: Garcia | D11: Female | E11: Japan | F11: Kobe | G11: +81271076059 | H11: sophia.garcia92@hotmail.com | I11: 84.381956 | J11: 1896.88 | K11: 431.23 | M11: {=_xlfn.XLOOKUP(A11,subscriptions!B11:B10004,subscriptions!D11:D10004)} -> 50 | N11: {=_xlfn.XLOOKUP(A11,subscriptions!B11:B10004,subscriptions!G11:G10004)} -> 10 | O11: 45 | P11: {=_xlfn.XLOOKUP(A11,subscriptions!B11:B10004,subscriptions!C11:C10004)} -> Mini | Q11: Large discount | R11: Low Value | S11: 2025:10
A12: aa0uHK | B12: Anthony | C12: King | D12: Male | E12: United States | F12: San Diego | G12: +1922134438 | H12: anthony.king92@zoho.com | I12: 84.170984 | J12: 81.2 | K12: 21.76 | M12: {=_xlfn.XLOOKUP(A12,subscriptions!B12:B10004,subscriptions!D12:D10004)} -> 120 | N12: {=_xlfn.XLOOKUP(A12,subscriptions!B12:B10004,subscriptions!G12:G10004)} -> 20 | O12: 96 | P12: {=_xlfn.XLOOKUP(A12,subscriptions!B12:B10004,subscriptions!C12:C10004)} -> Residential | Q12: Large discount | R12: Low Value | S12: 2020:06
A13: UKx7ti | B13: Liam | C13: Baker | D13: Male | E13: Brazil | F13: São Paulo | G13: +55341956450 | H13: liam.baker34@gmail.com | I13: 84.41772 | J13: 5305.34 | K13: 1186.84 | M13: {=_xlfn.XLOOKUP(A13,subscriptions!B13:B10004,subscriptions!D13:D10004)} -> 120 | N13: {=_xlfn.XLOOKUP(A13,subscriptions!B13:B10004,subscriptions!G13:G10004)} -> 0 | O13: 120 | P13: {=_xlfn.XLOOKUP(A13,subscriptions!B13:B10004,subscriptions!C13:C10004)} -> Residential | Q13: No discount | R13: Medium Value | S13: 2026:01
A14: skEuuT | B14: Isabella | C14: Harris | D14: Female | E14: Australia | F14: Wollongong | G14: +61679022904 | H14: isabella.harris92@proton.me | I14: 84.209769 | J14: 2729.64 | K14: 313.8 | M14: {=_xlfn.XLOOKUP(A14,subscriptions!B14:B10004,subscriptions!D14:D10004)} -> 120 | N14: {=_xlfn.XLOOKUP(A14,subscriptions!B14:B10004,subscriptions!G14:G10004)} -> 5 | O14: 114 | P14: {=_xlfn.XLOOKUP(A14,subscriptions!B14:B10004,subscriptions!C14:C10004)} -> Residential | Q14: Small discount | R14: Medium Value | S14: 2021:02
A15: es67gS | B15: Kenneth | C15: Jackson | D15: Male | E15: Ukraine | F15: Zaporizhzhia | G15: +380190879250 | H15: kenneth.jackson81@gmail.com | I15: 84.296667 | J15: 408.03 | K15: 101.87 | L15: 100 | M15: {=_xlfn.XLOOKUP(A15,subscriptions!B15:B10004,subscriptions!D15:D10004)} -> 120 | N15: {=_xlfn.XLOOKUP(A15,subscriptions!B15:B10004,subscriptions!G15:G10004)} -> 10 | O15: 108 | P15: {=_xlfn.XLOOKUP(A15,subscriptions!B15:B10004,subscriptions!C15:C10004)} -> Residential | Q15: Large discount | R15: Medium Value | S15: 2023:07
A16: JMLMUA | B16: Ava | C16: King | D16: Female | E16: Japan | F16: Fukuoka | G16: +81597817248 | H16: ava.king78@icloud.com | I16: 84.213947 | J16: 351.02 | K16: 69.83 | M16: {=_xlfn.XLOOKUP(A16,subscriptions!B16:B10004,subscriptions!D16:D10004)} -> 120 | N16: {=_xlfn.XLOOKUP(A16,subscriptions!B16:B10004,subscriptions!G16:G10004)} -> 20 | O16: 96 | P16: {=_xlfn.XLOOKUP(A16,subscriptions!B16:B10004,subscriptions!C16:C10004)} -> Residential | Q16: Large discount | R16: Low Value | S16: 2021:08
A17: U9T9pj | B17: Donna | C17: Carter | D17: Female | E17: Germany | F17: Frankfurt | G17: +49399863792 | H17: donna.carter17@gmail.com | I17: 84.297373 | J17: 353.92 | K17: 39.62 | M17: {=_xlfn.XLOOKUP(A17,subscriptions!B17:B10004,subscriptions!D17:D10004)} -> 80 | N17: {=_xlfn.XLOOKUP(A17,subscriptions!B17:B10004,subscriptions!G17:G10004)} -> 0 | O17: 80 | P17: {=_xlfn.XLOOKUP(A17,subscriptions!B17:B10004,subscriptions!C17:C10004)} -> Roam | Q17: No discount | R17: Low Value | S17: 2023:08
A18: qSHy5g | B18: Dorothy | C18: Baker | D18: Female | E18: Japan | F18: Kawasaki | G18: +81127422319 | H18: dorothy.baker62@yahoo.com | I18: 84.341296 | J18: 594.13 | K18: 119.72 | M18: {=_xlfn.XLOOKUP(A18,subscriptions!B18:B10004,subscriptions!D18:D10004)} -> 120 | N18: {=_xlfn.XLOOKUP(A18,subscriptions!B18:B10004,subscriptions!G18:G10004)} -> 5 | O18: 114 | P18: {=_xlfn.XLOOKUP(A18,subscriptions!B18:B10004,subscriptions!C18:C10004)} -> Residential | Q18: Small discount | R18: Medium Value | S18: 2024:11
A19: W13KgQ | B19: Ryan | C19: Thomas | D19: Male | E19: Australia | F19: Perth | G19: +61953525647 | H19: ryan.thomas90@gmail.com | I19: 84.211262 | J19: 1165.89 | K19: 161.14 | M19: {=_xlfn.XLOOKUP(A19,subscriptions!B19:B10004,subscriptions!D19:D10004)} -> 120 | N19: {=_xlfn.XLOOKUP(A19,subscriptions!B19:B10004,subscriptions!G19:G10004)} -> 10 | O19: 108 | P19: {=_xlfn.XLOOKUP(A19,subscriptions!B19:B10004,subscriptions!C19:C10004)} -> Residential | Q19: Large discount | R19: Medium Value | S19: 2021:04
A20: 5Kk3x9 | B20: Paul | C20: Wilson | D20: Male | E20: United Kingdom | F20: Edinburgh | G20: +44117412829 | H20: paul.wilson21@zoho.com | I20: 84.216771 | J20: 898.31 | K20: 94.12 | M20: {=_xlfn.XLOOKUP(A20,subscriptions!B20:B10004,subscriptions!D20:D10004)} -> 120 | N20: {=_xlfn.XLOOKUP(A20,subscriptions!B20:B10004,subscriptions!G20:G10004)} -> 20 | O20: 96 | P20: {=_xlfn.XLOOKUP(A20,subscriptions!B20:B10004,subscriptions!C20:C10004)} -> Residential | Q20: Large discount | R20: Low Value | S20: 2021:12
A21: GWzwYV | B21: Michelle | C21: Flores | D21: Female | E21: Canada | F21: Montreal | G21: +1250554165 | H21: michelle.flores14@yahoo.com | I21: 84.257292 | J21: 566.33 | K21: 88.51 | M21: {=_xlfn.XLOOKUP(A21,subscriptions!B21:B10004,subscriptions!D21:D10004)} -> 120 | N21: {=_xlfn.XLOOKUP(A21,subscriptions!B21:B10004,subscriptions!G21:G10004)} -> 0 | O21: 120 | P21: {=_xlfn.XLOOKUP(A21,subscriptions!B21:B10004,subscriptions!C21:C10004)} -> Residential | Q21: No discount | R21: Medium Value | S21: 2022:10
A22: ByT8KG | B22: Margaret | C22: Davis | D22: Female | E22: United States | F22: San Diego | G22: +1350076354 | H22: margaret.davis49@outlook.com | I22: 84.255116 | J22: 1469.56 | K22: 286.36 | M22: {=_xlfn.XLOOKUP(A22,subscriptions!B22:B10004,subscriptions!D22:D10004)} -> 250 | N22: {=_xlfn.XLOOKUP(A22,subscriptions!B22:B10004,subscriptions!G22:G10004)} -> 5 | O22: 237.5 | P22: {=_xlfn.XLOOKUP(A22,subscriptions!B22:B10004,subscriptions!C22:C10004)} -> Business | Q22: Small discount | R22: High Value | S22: 2022:07
A23: dfr6n4 | B23: Paul | C23: White | D23: Male | E23: Japan | F23: Yokohama | G23: +81469368234 | H23: paul.white20@gmail.com | I23: 84.174514 | J23: 275.35 | K23: 75.87 | M23: {=_xlfn.XLOOKUP(A23,subscriptions!B23:B10004,subscriptions!D23:D10004)} -> 250 | N23: {=_xlfn.XLOOKUP(A23,subscriptions!B23:B10004,subscriptions!G23:G10004)} -> 10 | O23: 225 | P23: {=_xlfn.XLOOKUP(A23,subscriptions!B23:B10004,subscriptions!C23:C10004)} -> Business | Q23: Large discount | R23: High Value | S23: 2020:11
A24: hNk0Aq | B24: William | C24: Lopez | D24: Male | E24: Australia | F24: Sydney | G24: +61231549005 | H24: william.lopez15@yahoo.com | I24: 84.299352 | J24: 568.27 | K24: 63.27 | M24: {=_xlfn.XLOOKUP(A24,subscriptions!B24:B10004,subscriptions!D24:D10004)} -> 120 | N24: {=_xlfn.XLOOKUP(A24,subscriptions!B24:B10004,subscriptions!G24:G10004)} -> 20 | O24: 96 | P24: {=_xlfn.XLOOKUP(A24,subscriptions!B24:B10004,subscriptions!C24:C10004)} -> Residential | Q24: Large discount | R24: Low Value | S24: 2023:11
A25: hOliKx | B25: Sarah | C25: Williams | D25: Female | E25: Brazil | F25: Brasília | G25: +55567722939 | H25: sarah.williams22@proton.me | I25: 84.174421 | J25: 734.42 | K25: 152.51 | M25: {=_xlfn.XLOOKUP(A25,subscriptions!B25:B10004,subscriptions!D25:D10004)} -> 50 | N25: {=_xlfn.XLOOKUP(A25,subscriptions!B25:B10004,subscriptions!G25:G10004)} -> 0 | O25: 50 | P25: {=_xlfn.XLOOKUP(A25,subscriptions!B25:B10004,subscriptions!C25:C10004)} -> Mini | Q25: No discount | R25: Low Value | S25: 2020:11
A26: jLHaed | B26: Ethan | C26: Hernandez | D26: Male | E26: United Kingdom | F26: Birmingham | G26: +44876434186 | H26: ethan.hernandez43@hotmail.com | I26: 84.335764 | J26: 963.4 | K26: 249.96 | M26: {=_xlfn.XLOOKUP(A26,subscriptions!B26:B10004,subscriptions!D26:D10004)} -> 80 | N26: {=_xlfn.XLOOKUP(A26,subscriptions!B26:B10004,subscriptions!G26:G10004)} -> 5 | O26: 76 | P26: {=_xlfn.XLOOKUP(A26,subscriptions!B26:B10004,subscriptions!C26:C10004)} -> Roam | Q26: Small discount | R26: Low Value | S26: 2024:03
A27: LDhepH | B27: Stephanie | C27: King | D27: Female | E27: Canada | F27: Halifax | G27: +1297209972 | H27: stephanie.king65@zoho.com | I27: 84.292419 | J27: 2356.9 | K27: 295.54 | M27: {=_xlfn.XLOOKUP(A27,subscriptions!B27:B10004,subscriptions!D27:D10004)} -> 120 | N27: {=_xlfn.XLOOKUP(A27,subscriptions!B27:B10004,subscriptions!G27:G10004)} -> 10 | O27: 108 | P27: {=_xlfn.XLOOKUP(A27,subscriptions!B27:B10004,subscriptions!C27:C10004)} -> Residential | Q27: Large discount | R27: Medium Value | S27: 2023:01
A28: XP7tS6 | B28: Lucas | C28: King | D28: Male | E28: Canada | F28: Ottawa | G28: +1602733126 | H28: lucas.king79@hotmail.com | I28: 84.257708 | J28: 384.1 | K28: 44.8 | M28: {=_xlfn.XLOOKUP(A28,subscriptions!B28:B10004,subscriptions!D28:D10004)} -> 120 | N28: {=_xlfn.XLOOKUP(A28,subscriptions!B28:B10004,subscriptions!G28:G10004)} -> 20 | O28: 96 | P28: {=_xlfn.XLOOKUP(A28,subscriptions!B28:B10004,subscriptions!C28:C10004)} -> Residential | Q28: Large discount | R28: Low Value | S28: 2022:11
A29: nRIaQU | B29: Margaret | C29: Wright | D29: Female | E29: United States | F29: Philadelphia | G29: +1764862550 | H29: margaret.wright25@icloud.com | I29: 84.340382 | J29: 1133.04 | K29: 267.45 | M29: {=_xlfn.XLOOKUP(A29,subscriptions!B29:B10004,subscriptions!D29:D10004)} -> 120 | N29: {=_xlfn.XLOOKUP(A29,subscriptions!B29:B10004,subscriptions!G29:G10004)} -> 0 | O29: 120 | P29: {=_xlfn.XLOOKUP(A29,subscriptions!B29:B10004,subscriptions!C29:C10004)} -> Residential | Q29: No discount | R29: Medium Value | S29: 2024:10
A30: U3jmDP | B30: Ryan | C30: White | D30: Male | E30: Australia | F30: Hobart | G30: +61275874740 | H30: ryan.white13@zoho.com | I30: 84.25728 | J30: 1396.26 | K30: 157.47 | M30: {=_xlfn.XLOOKUP(A30,subscriptions!B30:B10004,subscriptions!D30:D10004)} -> 120 | N30: {=_xlfn.XLOOKUP(A30,subscriptions!B30:B10004,subscriptions!G30:G10004)} -> 5 | O30: 114 | P30: {=_xlfn.XLOOKUP(A30,subscriptions!B30:B10004,subscriptions!C30:C10004)} -> Residential | Q30: Small discount | R30: Medium Value | S30: 2022:10
A31: w37dxn | B31: Lucas | C31: Clark | D31: Male | E31: France | F31: Nice | G31: +33788596627 | H31: lucas.clark92@gmail.com | I31: 84.334861 | J31: 121.35 | K31: 32.35 | M31: {=_xlfn.XLOOKUP(A31,subscriptions!B31:B10004,subscriptions!D31:D10004)} -> 120 | N31: {=_xlfn.XLOOKUP(A31,subscriptions!B31:B10004,subscriptions!G31:G10004)} -> 10 | O31: 108 | P31: {=_xlfn.XLOOKUP(A31,subscriptions!B31:B10004,subscriptions!C31:C10004)} -> Residential | Q31: Large discount | R31: Medium Value | S31: 2024:02
A32: RhL75X | B32: Steven | C32: Lewis | D32: Male | E32: United Kingdom | F32: Edinburgh | G32: +44407796853 | H32: steven.lewis97@zoho.com | I32: 84.2961 | J32: 1453 | K32: 194.25 | M32: {=_xlfn.XLOOKUP(A32,subscriptions!B32:B10004,subscriptions!D32:D10004)} -> 80 | N32: {=_xlfn.XLOOKUP(A32,subscriptions!B32:B10004,subscriptions!G32:G10004)} -> 20 | O32: 64 | P32: {=_xlfn.XLOOKUP(A32,subscriptions!B32:B10004,subscriptions!C32:C10004)} -> Roam | Q32: Large discount | R32: Low Value | S32: 2023:06
A33: yQF57Q | B33: George | C33: Allen | D33: Male | E33: Canada | F33: Edmonton | G33: +1520431650 | H33: george.allen15@outlook.com | I33: 84.382697 | J33: 330.44 | K33: 85.36 | M33: {=_xlfn.XLOOKUP(A33,subscriptions!B33:B10004,subscriptions!D33:D10004)} -> 120 | N33: {=_xlfn.XLOOKUP(A33,subscriptions!B33:B10004,subscriptions!G33:G10004)} -> 0 | O33: 120 | P33: {=_xlfn.XLOOKUP(A33,subscriptions!B33:B10004,subscriptions!C33:C10004)} -> Residential | Q33: No discount | R33: Medium Value | S33: 2025:11
A34: 0PBrlL | B34: Sophia | C34: Campbell | D34: Female | E34: Germany | F34: Düsseldorf | G34: +49098370145 | H34: sophia.campbell67@zoho.com | I34: 84.296551 | J34: 150.9 | K34: 52.7 | M34: {=_xlfn.XLOOKUP(A34,subscriptions!B34:B10004,subscriptions!D34:D10004)} -> 120 | N34: {=_xlfn.XLOOKUP(A34,subscriptions!B34:B10004,subscriptions!G34:G10004)} -> 5 | O34: 114 | P34: {=_xlfn.XLOOKUP(A34,subscriptions!B34:B10004,subscriptions!C34:C10004)} -> Residential | Q34: Small discount | R34: Medium Value | S34: 2023:07
A35: 9gdxMv | B35: James | C35: Lee | D35: Male | E35: Brazil | F35: Manaus | G35: +55119849093 | H35: james.lee97@proton.me | I35: 84.379988 | J35: 4510.53 | K35: 786.54 | M35: {=_xlfn.XLOOKUP(A35,subscriptions!B35:B10004,subscriptions!D35:D10004)} -> 120 | N35: {=_xlfn.XLOOKUP(A35,subscriptions!B35:B10004,subscriptions!G35:G10004)} -> 10 | O35: 108 | P35: {=_xlfn.XLOOKUP(A35,subscriptions!B35:B10004,subscriptions!C35:C10004)} -> Residential | Q35: Large discount | R35: Medium Value | S35: 2025:07
A36: 5eSD5N | B36: Kevin | C36: Walker | D36: Male | E36: Ukraine | F36: Lviv | G36: +380442809816 | H36: kevin.walker31@outlook.com | I36: 84.297338 | J36: 5105.95 | K36: 899.53 | L36: 100 | M36: {=_xlfn.XLOOKUP(A36,subscriptions!B36:B10004,subscriptions!D36:D10004)} -> 50 | N36: {=_xlfn.XLOOKUP(A36,subscriptions!B36:B10004,subscriptions!G36:G10004)} -> 20 | O36: 40 | P36: {=_xlfn.XLOOKUP(A36,subscriptions!B36:B10004,subscriptions!C36:C10004)} -> Mini | Q36: Large discount | R36: Low Value | S36: 2023:08
A37: wvOpOK | B37: Sofia | C37: Flores | D37: Female | E37: Spain | F37: Las Palmas | G37: +34822753542 | H37: sofia.flores30@hotmail.com | I37: 84.339722 | J37: 2528.5 | K37: 623.28 | M37: {=_xlfn.XLOOKUP(A37,subscriptions!B37:B10004,subscriptions!D37:D10004)} -> 120 | N37: {=_xlfn.XLOOKUP(A37,subscriptions!B37:B10004,subscriptions!G37:G10004)} -> 0 | O37: 120 | P37: {=_xlfn.XLOOKUP(A37,subscriptions!B37:B10004,subscriptions!C37:C10004)} -> Residential | Q37: No discount | R37: Medium Value | S37: 2024:09
A38: 3JOLXy | B38: Santiago | C38: Martinez | D38: Male | E38: Australia | F38: Newcastle | G38: +61134916527 | H38: santiago.martinez41@yahoo.com | I38: 84.379896 | J38: 594.93 | K38: 132.46 | M38: {=_xlfn.XLOOKUP(A38,subscriptions!B38:B10004,subscriptions!D38:D10004)} -> 250 | N38: {=_xlfn.XLOOKUP(A38,subscriptions!B38:B10004,subscriptions!G38:G10004)} -> 5 | O38: 237.5 | P38: {=_xlfn.XLOOKUP(A38,subscriptions!B38:B10004,subscriptions!C38:C10004)} -> Business | Q38: Small discount | R38: High Value | S38: 2025:07
A39: QciFoE | B39: Betty | C39: Hall | D39: Female | E39: Japan | F39: Fukuoka | G39: +81977115967 | H39: betty.hall67@gmail.com | I39: 84.380833 | J39: 204.17 | K39: 33.26 | M39: {=_xlfn.XLOOKUP(A39,subscriptions!B39:B10004,subscriptions!D39:D10004)} -> 120 | N39: {=_xlfn.XLOOKUP(A39,subscriptions!B39:B10004,subscriptions!G39:G10004)} -> 10 | O39: 108 | P39: {=_xlfn.XLOOKUP(A39,subscriptions!B39:B10004,subscriptions!C39:C10004)} -> Residential | Q39: Large discount | R39: Medium Value | S39: 2025:08
A40: LSmzQQ | B40: Laura | C40: Robinson | D40: Female | E40: United Kingdom | F40: Edinburgh | G40: +44266107174 | H40: laura.robinson60@zoho.com | I40: 84.210775 | J40: 1779.13 | K40: 186.04 | M40: {=_xlfn.XLOOKUP(A40,subscriptions!B40:B10004,subscriptions!D40:D10004)} -> 80 | N40: {=_xlfn.XLOOKUP(A40,subscriptions!B40:B10004,subscriptions!G40:G10004)} -> 20 | O40: 64 | P40: {=_xlfn.XLOOKUP(A40,subscriptions!B40:B10004,subscriptions!C40:C10004)} -> Roam | Q40: Large discount | R40: Low Value | S40: 2021:03
...

Sheet subscriptions
A1: subscription_id | B1: customer_id | C1: plan_name | D1: monthly_fee | E1: status | F1: start_date | G1: discount_percent
A2: 1 | B2: DxSAVy | C2: Residential | D2: 120 | E2: Paused | F2: 44927 | G2: 5
A3: 2 | B3: 5NXFhm | C3: Business | D3: 250 | E3: Active | F3: 44927 | G3: 10
A4: 3 | B4: x2uJPT | C4: Mini | D4: 50 | E4: Active | F4: 44927 | G4: 20
A5: 4 | B5: tB7Ut2 | C5: Mini | D5: 50 | E5: Active | F5: 44927 | G5: 0
A6: 5 | B6: i4A2yx | C6: Mini | D6: 50 | E6: Cancelled | F6: 44927 | G6: 5
A7: 6 | B7: u27pCF | C7: Residential | D7: 120 | E7: Paused | F7: 44927 | G7: 10
A8: 7 | B8: SylVYM | C8: Roam | D8: 80 | E8: Active | F8: 44927 | G8: 20
A9: 8 | B9: Pdbbe3 | C9: Residential | D9: 120 | E9: Active | F9: 44927 | G9: 0
A10: 9 | B10: ZLANQw | C10: Residential | D10: 120 | E10: Active | F10: 44927 | G10: 5
A11: 10 | B11: yjbWTZ | C11: Mini | D11: 50 | E11: Active | F11: 44927 | G11: 10
A12: 11 | B12: aa0uHK | C12: Residential | D12: 120 | E12: Active | F12: 44927 | G12: 20
A13: 12 | B13: UKx7ti | C13: Residential | D13: 120 | E13: Active | F13: 44927 | G13: 0
... A9857: 9856 | B9857: guyDWG | C9857: Residential | D9857: 120 | E9857: Active | F9857: 44927 | G9857: 0
A9858: 9857 | B9858: 702938 | C9858: Business | D9858: 250 | E9858: Active | F9858: 44927 | G9858: 5
A9859: 9858 | B9859: P2jKe1 | C9859: Mini | D9859: 50 | E9859: Active | F9859: 44927 | G9859: 10
A9860: 9859 | B9860: YqyxzJ | C9860: Residential | D9860: 120 | E9860: Active | F9860: 44927 | G9860: 20
A9861: 9860 | B9861: F8Lozo | C9861: Residential | D9861: 120 | E9861: Active | F9861: 44927 | G9861: 0
A9862: 9861 | B9862: UBHtYD | C9862: Roam | D9862: 80 | E9862: Active | F9862: 44927 | G9862: 5
A9863: 9862 | B9863: bsjfV6 | C9863: Roam | D9863: 80 | E9863: Active | F9863: 44927 | G9863: 10
A9864: 9863 | B9864: YrEbty | C9864: Business | D9864: 250 | E9864: Active | F9864: 44927 | G9864: 20
A9865: 9864 | B9865: 6P89xb | C9865: Residential | D9865: 120 | E9865: Cancelled | F9865: 44927 | G9865: 0
A9866: 9865 | B9866: MclPUu | C9866: Mini | D9866: 50 | E9866: Active | F9866: 44927 | G9866: 5
A9867: 9866 | B9867: cmuKyC | C9867: Mini | D9867: 50 | E9867: Active | F9867: 44927 | G9867: 10
A9868: 9867 | B9868: ouQ6i1 | C9868: Residential | D9868: 120 | E9868: Active | F9868: 44927 | G9868: 20
A9869: 9868 | B9869: RFy1ul | C9869: Residential | D9869: 120 | E9869: Active | F9869: 44927 | G9869: 0
A9870: 9869 | B9870: 5AWD2p | C9870: Residential | D9870: 120 | E9870: Active | F9870: 44927 | G9870: 5
... A10001: 10000 | B10001: d5gjoO | C10001: Roam | D10001: 80 | E10001: Cancelled | F10001: 44927 | G10001: 0

Sheet Task #1
A1: TASK 01 — CUSTOMER DISTRIBUTION
A3: Business Question:
A4: How many customers do we have in each country?
A6: Country | B6: Customers
A7: =IFERROR(__xludf.DUMMYFUNCTION("QUERY(RawData!E2:E10002,""SELECT E, COUNT(E) group by E"",0)"),"") | B7: =IFERROR(__xludf.DUMMYFUNCTION("""COMPUTED_VALUE"""),"count ") -> count
A8: =IFERROR(__xludf.DUMMYFUNCTION("""COMPUTED_VALUE"""),"Australia") -> Australia | B8: =IFERROR(__xludf.DUMMYFUNCTION("""COMPUTED_VALUE"""),1030.0) -> 1030
A9: =IFERROR(__xludf.DUMMYFUNCTION("""COMPUTED_VALUE"""),"Brazil") -> Brazil | B9: =IFERROR(__xludf.DUMMYFUNCTION("""COMPUTED_VALUE"""),996.0) -> 996
A10: =IFERROR(__xludf.DUMMYFUNCTION("""COMPUTED_VALUE"""),"Canada") -> Canada | B10: =IFERROR(__xludf.DUMMYFUNCTION("""COMPUTED_VALUE"""),997.0) -> 997
A11: =IFERROR(__xludf.DUMMYFUNCTION("""COMPUTED_VALUE"""),"France") -> France | B11: =IFERROR(__xludf.DUMMYFUNCTION("""COMPUTED_VALUE"""),996.0) -> 996
A12: =IFERROR(__xludf.DUMMYFUNCTION("""COMPUTED_VALUE"""),"Germany") -> Germany | B12: =IFERROR(__xludf.DUMMYFUNCTION("""COMPUTED_VALUE"""),1027.0) -> 1027
A13: =IFERROR(__xludf.DUMMYFUNCTION("""COMPUTED_VALUE"""),"Japan") -> Japan | B13: =IFERROR(__xludf.DUMMYFUNCTION("""COMPUTED_VALUE"""),973.0) -> 973
A14: =IFERROR(__xludf.DUMMYFUNCTION("""COMPUTED_VALUE"""),"Spain") -> Spain | B14: =IFERROR(__xludf.DUMMYFUNCTION("""COMPUTED_VALUE"""),1019.0) -> 1019
A15: =IFERROR(__xludf.DUMMYFUNCTION("""COMPUTED_VALUE"""),"Ukraine") -> Ukraine | B15: =IFERROR(__xludf.DUMMYFUNCTION("""COMPUTED_VALUE"""),1032.0) -> 1032
A16: =IFERROR(__xludf.DUMMYFUNCTION("""COMPUTED_VALUE"""),"United Kingdom") -> United Kingdom | B16: =IFERROR(__xludf.DUMMYFUNCTION("""COMPUTED_VALUE"""),977.0) -> 977
A17: =IFERROR(__xludf.DUMMYFUNCTION("""COMPUTED_VALUE"""),"United States") -> United States | B17: =IFERROR(__xludf.DUMMYFUNCTION("""COMPUTED_VALUE"""),954.0) -> 954
A18: TOTAL: | B18: =SUM(B7:B17) -> 10001
A20: Key Findings:
A21: Ukraine has the highest number of customers (1,031), while the United States has the lowest (954). The customer distribution across countries is relatively even, with each country representing approximately 10% of the total customer base.

Sheet Task #2
A1: TASK 02 — REVENUE BY COUNTRY
A3: Business Question:
A4: Which countries generate the highest total revenue?
A6: Country | B6: Total Revenue
A7: =IFERROR(__xludf.DUMMYFUNCTION("QUERY(RawData!E2:O10002,""SELECT E, SUM(O) GROUP BY E ORDER BY SUM(O) DESC"",0)"),"") | B7: =IFERROR(__xludf.DUMMYFUNCTION("""COMPUTED_VALUE"""),"sum ") -> sum
A8: =IFERROR(__xludf.DUMMYFUNCTION("""COMPUTED_VALUE"""),"Spain") -> Spain | B8: =IFERROR(__xludf.DUMMYFUNCTION("""COMPUTED_VALUE"""),111793.0) -> 111793
A9: =IFERROR(__xludf.DUMMYFUNCTION("""COMPUTED_VALUE"""),"Ukraine") -> Ukraine | B9: =IFERROR(__xludf.DUMMYFUNCTION("""COMPUTED_VALUE"""),111619.0) -> 111619
A10: =IFERROR(__xludf.DUMMYFUNCTION("""COMPUTED_VALUE"""),"Australia") -> Australia | B10: =IFERROR(__xludf.DUMMYFUNCTION("""COMPUTED_VALUE"""),111119.5) -> 111119.5
A11: =IFERROR(__xludf.DUMMYFUNCTION("""COMPUTED_VALUE"""),"Canada") -> Canada | B11: =IFERROR(__xludf.DUMMYFUNCTION("""COMPUTED_VALUE"""),109096.5) -> 109096.5
A12: =IFERROR(__xludf.DUMMYFUNCTION("""COMPUTED_VALUE"""),"Germany") -> Germany | B12: =IFERROR(__xludf.DUMMYFUNCTION("""COMPUTED_VALUE"""),108088.0) -> 108088
A13: =IFERROR(__xludf.DUMMYFUNCTION("""COMPUTED_VALUE"""),"France") -> France | B13: =IFERROR(__xludf.DUMMYFUNCTION("""COMPUTED_VALUE"""),107789.0) -> 107789
A14: =IFERROR(__xludf.DUMMYFUNCTION("""COMPUTED_VALUE"""),"Japan") -> Japan | B14: =IFERROR(__xludf.DUMMYFUNCTION("""COMPUTED_VALUE"""),107010.0) -> 107010
A15: =IFERROR(__xludf.DUMMYFUNCTION("""COMPUTED_VALUE"""),"Brazil") -> Brazil | B15: =IFERROR(__xludf.DUMMYFUNCTION("""COMPUTED_VALUE"""),105391.0) -> 105391
A16: =IFERROR(__xludf.DUMMYFUNCTION("""COMPUTED_VALUE"""),"United States") -> United States | B16: =IFERROR(__xludf.DUMMYFUNCTION("""COMPUTED_VALUE"""),104221.5) -> 104221.5
A17: =IFERROR(__xludf.DUMMYFUNCTION("""COMPUTED_VALUE"""),"United Kingdom") -> United Kingdom | B17: =IFERROR(__xludf.DUMMYFUNCTION("""COMPUTED_VALUE"""),103806.0) -> 103806
A18: TOTAL: | B18: =SUM(B7:B17) -> 1079933.5
A20: Key Findings:
A21: Spain generates the highest total revenue at $111,793, while the United States generates the lowest at $104,222. The relatively small difference suggests that total revenue is fairly evenly distributed across countries.

Sheet Task #3
A1: TASK 03 — AVERAGE REVENUE PER CUSTOMER
A3: Business Question:
A4: Which countries have the highest average revenue per customer?
A6: Country | B6: Average Revenue
A7: =IFERROR(__xludf.DUMMYFUNCTION("QUERY(RawData!E2:O10002,""SELECT E, AVG(O) GROUP BY E ORDER BY AVG(O) DESC"",0)"),"") | B7: =IFERROR(__xludf.DUMMYFUNCTION("""COMPUTED_VALUE"""),"avg ") -> avg
A8: =IFERROR(__xludf.DUMMYFUNCTION("""COMPUTED_VALUE"""),"Japan") -> Japan | B8: =IFERROR(__xludf.DUMMYFUNCTION("""COMPUTED_VALUE"""),109.97944501541623) -> 109.97944
A9: =IFERROR(__xludf.DUMMYFUNCTION("""COMPUTED_VALUE"""),"Spain") -> Spain | B9: =IFERROR(__xludf.DUMMYFUNCTION("""COMPUTED_VALUE"""),109.70853778213936) -> 109.70854
A10: =IFERROR(__xludf.DUMMYFUNCTION("""COMPUTED_VALUE"""),"Canada") -> Canada | B10: =IFERROR(__xludf.DUMMYFUNCTION("""COMPUTED_VALUE"""),109.4247743229689) -> 109.42477
A11: =IFERROR(__xludf.DUMMYFUNCTION("""COMPUTED_VALUE"""),"United States") -> United States | B11: =IFERROR(__xludf.DUMMYFUNCTION("""COMPUTED_VALUE"""),109.24685534591195) -> 109.24686
A12: =IFERROR(__xludf.DUMMYFUNCTION("""COMPUTED_VALUE"""),"Ukraine") -> Ukraine | B12: =IFERROR(__xludf.DUMMYFUNCTION("""COMPUTED_VALUE"""),108.26285160038798) -> 108.26285
A13: =IFERROR(__xludf.DUMMYFUNCTION("""COMPUTED_VALUE"""),"France") -> France | B13: =IFERROR(__xludf.DUMMYFUNCTION("""COMPUTED_VALUE"""),108.2218875502008) -> 108.22189
A14: =IFERROR(__xludf.DUMMYFUNCTION("""COMPUTED_VALUE"""),"Australia") -> Australia | B14: =IFERROR(__xludf.DUMMYFUNCTION("""COMPUTED_VALUE"""),107.88300970873786) -> 107.88301
A15: =IFERROR(__xludf.DUMMYFUNCTION("""COMPUTED_VALUE"""),"United Kingdom") -> United Kingdom | B15: =IFERROR(__xludf.DUMMYFUNCTION("""COMPUTED_VALUE"""),106.24974411463664) -> 106.24974
A16: =IFERROR(__xludf.DUMMYFUNCTION("""COMPUTED_VALUE"""),"Brazil") -> Brazil | B16: =IFERROR(__xludf.DUMMYFUNCTION("""COMPUTED_VALUE"""),105.81425702811245) -> 105.81426
A17: =IFERROR(__xludf.DUMMYFUNCTION("""COMPUTED_VALUE"""),"Germany") -> Germany | B17: =IFERROR(__xludf.DUMMYFUNCTION("""COMPUTED_VALUE"""),105.24634858812074) -> 105.24635
A20: Key Findings:
A21: Japan and Spain have the highest average revenue per customer, while Germany has the lowest. Overall, average revenue per customer is relatively consistent across countries, with only a small difference between the highest and lowest values.

Sheet Task #4
A1: TASK 04 — REVENUE BY SUBSCRIPTION PLAN
A3: Business Question:
A4: Which subscription plans generate the most revenue?
A6: Plan_name | B6: Total Revenue | C6: Average | E6: Plan_name | F6: Customers Amount | H6: Amount of users without plan_name | I6: Unique_id
A7: =IFERROR(__xludf.DUMMYFUNCTION("QUERY(RawData!O2:P10002,""SELECT P, SUM(O) GROUP BY P ORDER BY SUM(O) DESC"",0)"),"") | B7: =IFERROR(__xludf.DUMMYFUNCTION("""COMPUTED_VALUE"""),"sum ") -> sum | E7: =IFERROR(__xludf.DUMMYFUNCTION("QUERY(RawData!O2:P10002,""SELECT P, COUNT(P) GROUP BY P"",0)"),"") | F7: =IFERROR(__xludf.DUMMYFUNCTION("""COMPUTED_VALUE"""),"count ") -> count | H7: {=SUM(--ISNA(RawData!P2:P10002))} -> 1 | I7: =IFERROR(__xludf.DUMMYFUNCTION("FILTER(RawData!A2:A10002,ISNA(RawData!P2:P10002))"),"SV39ac") -> SV39ac
A8: =IFERROR(__xludf.DUMMYFUNCTION("""COMPUTED_VALUE"""),"Residential") -> Residential | B8: =IFERROR(__xludf.DUMMYFUNCTION("""COMPUTED_VALUE"""),652512.0) -> 652512 | C8: =B8/_xlfn.XLOOKUP(A8,E$8:E$12,F$8:F$12) -> 109.50025 | E8: =IFERROR(__xludf.DUMMYFUNCTION("""COMPUTED_VALUE"""),"#N/A") -> #N/A | F8: =IFERROR(__xludf.DUMMYFUNCTION("""COMPUTED_VALUE"""),1.0) -> 1
A9: =IFERROR(__xludf.DUMMYFUNCTION("""COMPUTED_VALUE"""),"Business") -> Business | B9: =IFERROR(__xludf.DUMMYFUNCTION("""COMPUTED_VALUE"""),232787.5) -> 232787.5 | C9: =B9/_xlfn.XLOOKUP(A9,E$8:E$12,F$8:F$12) -> 228.44701 | E9: =IFERROR(__xludf.DUMMYFUNCTION("""COMPUTED_VALUE"""),"Business") -> Business | F9: =IFERROR(__xludf.DUMMYFUNCTION("""COMPUTED_VALUE"""),1019.0) -> 1019
A10: =IFERROR(__xludf.DUMMYFUNCTION("""COMPUTED_VALUE"""),"Roam") -> Roam | B10: =IFERROR(__xludf.DUMMYFUNCTION("""COMPUTED_VALUE"""),151524.0) -> 151524 | C10: =B10/_xlfn.XLOOKUP(A10,E$8:E$12,F$8:F$12) -> 72.918191 | E10: =IFERROR(__xludf.DUMMYFUNCTION("""COMPUTED_VALUE"""),"Mini") -> Mini | F10: =IFERROR(__xludf.DUMMYFUNCTION("""COMPUTED_VALUE"""),944.0) -> 944
A11: =IFERROR(__xludf.DUMMYFUNCTION("""COMPUTED_VALUE"""),"Mini") -> Mini | B11: =IFERROR(__xludf.DUMMYFUNCTION("""COMPUTED_VALUE"""),43110.0) -> 43110 | C11: =B11/_xlfn.XLOOKUP(A11,E$8:E$12,F$8:F$12) -> 45.667373 | E11: =IFERROR(__xludf.DUMMYFUNCTION("""COMPUTED_VALUE"""),"Residential") -> Residential | F11: =IFERROR(__xludf.DUMMYFUNCTION("""COMPUTED_VALUE"""),5959.0) -> 5959
A12: =IFERROR(__xludf.DUMMYFUNCTION("""COMPUTED_VALUE"""),"#N/A") -> #N/A | C12: =B12/_xlfn.XLOOKUP(A12,E$8:E$12,F$8:F$12) -> 0 | E12: =IFERROR(__xludf.DUMMYFUNCTION("""COMPUTED_VALUE"""),"Roam") -> Roam | F12: =IFERROR(__xludf.DUMMYFUNCTION("""COMPUTED_VALUE"""),2078.0) -> 2078
A20: Key Findings:
A21: The Residential plan generates the highest total revenue, primarily due to its significantly larger customer base. However, Business has a much higher average revenue per customer, indicating that Business customers generate more revenue individually. One customer in RawData does not have a matching subscription record and was excluded from the subscription-level analysis.

Sheet Task #5
A1: TASK 05 — DISCOUNT ANALYSIS
A3: Business Question:
A4: How do discounts affect monthly revenue?
A6: Discount_category | B6: Customers | D6: Total Revenue | E6: Avg Revenue/Customer
A7: =IFERROR(__xludf.DUMMYFUNCTION("QUERY(RawData!Q2:Q10002,""SELECT Q, COUNT(Q) GROUP BY Q ORDER BY COUNT(Q) DESC"",0)"),"") | B7: =IFERROR(__xludf.DUMMYFUNCTION("""COMPUTED_VALUE"""),"count ") -> count | C7: =IFERROR(__xludf.DUMMYFUNCTION("QUERY(RawData!O2:Q10002,""SELECT Q, SUM(O) GROUP BY Q ORDER BY SUM(O) DESC"",0)"),"") | D7: =IFERROR(__xludf.DUMMYFUNCTION("""COMPUTED_VALUE"""),"sum ") -> sum
A8: =IFERROR(__xludf.DUMMYFUNCTION("""COMPUTED_VALUE"""),"Large discount") -> Large discount | B8: =IFERROR(__xludf.DUMMYFUNCTION("""COMPUTED_VALUE"""),5000.0) -> 5000 | C8: =IFERROR(__xludf.DUMMYFUNCTION("""COMPUTED_VALUE"""),"Large discount") -> Large discount | D8: =IFERROR(__xludf.DUMMYFUNCTION("""COMPUTED_VALUE"""),504209.0) -> 504209 | E8: {=D8/_xlfn.XLOOKUP(A8,C$8:C$12,$B8:B$12)} -> 100.8418
A9: =IFERROR(__xludf.DUMMYFUNCTION("""COMPUTED_VALUE"""),"No discount") -> No discount | B9: =IFERROR(__xludf.DUMMYFUNCTION("""COMPUTED_VALUE"""),2500.0) -> 2500 | C9: =IFERROR(__xludf.DUMMYFUNCTION("""COMPUTED_VALUE"""),"No discount") -> No discount | D9: =IFERROR(__xludf.DUMMYFUNCTION("""COMPUTED_VALUE"""),297270.0) -> 297270 | E9: {=D9/_xlfn.XLOOKUP(A9,C$8:C$12,$B8:B$12)} -> 118.908
A10: =IFERROR(__xludf.DUMMYFUNCTION("""COMPUTED_VALUE"""),"Small discount") -> Small discount | B10: =IFERROR(__xludf.DUMMYFUNCTION("""COMPUTED_VALUE"""),2500.0) -> 2500 | C10: =IFERROR(__xludf.DUMMYFUNCTION("""COMPUTED_VALUE"""),"Small discount") -> Small discount | D10: =IFERROR(__xludf.DUMMYFUNCTION("""COMPUTED_VALUE"""),278454.5) -> 278454.5 | E10: {=D10/_xlfn.XLOOKUP(A10,C$8:C$12,$B8:B$12)} -> 111.3818
A11: =IFERROR(__xludf.DUMMYFUNCTION("""COMPUTED_VALUE"""),"#N/A") -> #N/A | B11: =IFERROR(__xludf.DUMMYFUNCTION("""COMPUTED_VALUE"""),1.0) -> 1 | C11: =IFERROR(__xludf.DUMMYFUNCTION("""COMPUTED_VALUE"""),"#N/A") -> #N/A
A20: Key Findings:
A21: This report shows that customers without a discount generate the highest average revenue per customer, while customers with large discounts generate the lowest. This suggests that larger discounts may reduce revenue per customer.

Sheet Task #6
A1: TASK 06 — CUSTOMER VALUE BY SUBSCRIPTION PLAN
A3: Business Question:
A4: Does the plan with the largest customer base also generate the highest revenue per customer?
A6: Plan name | B6: Customers | C6: Total revenue | D6: Avg revenue/Customer
A7: =IFERROR(__xludf.DUMMYFUNCTION("QUERY(RawData!O2:P10002,""SELECT P, COUNT(P), SUM(O) GROUP BY P ORDER BY SUM(O) DESC"",0)"),"") | B7: =IFERROR(__xludf.DUMMYFUNCTION("""COMPUTED_VALUE"""),"count ") -> count | C7: =IFERROR(__xludf.DUMMYFUNCTION("""COMPUTED_VALUE"""),"sum ") -> sum
A8: =IFERROR(__xludf.DUMMYFUNCTION("""COMPUTED_VALUE"""),"Residential") -> Residential | B8: =IFERROR(__xludf.DUMMYFUNCTION("""COMPUTED_VALUE"""),5959.0) -> 5959 | C8: =IFERROR(__xludf.DUMMYFUNCTION("""COMPUTED_VALUE"""),652512.0) -> 652512 | D8: =C8/B8 -> 109.50025
A9: =IFERROR(__xludf.DUMMYFUNCTION("""COMPUTED_VALUE"""),"Business") -> Business | B9: =IFERROR(__xludf.DUMMYFUNCTION("""COMPUTED_VALUE"""),1019.0) -> 1019 | C9: =IFERROR(__xludf.DUMMYFUNCTION("""COMPUTED_VALUE"""),232787.5) -> 232787.5 | D9: =C9/B9 -> 228.44701
A10: =IFERROR(__xludf.DUMMYFUNCTION("""COMPUTED_VALUE"""),"Roam") -> Roam | B10: =IFERROR(__xludf.DUMMYFUNCTION("""COMPUTED_VALUE"""),2078.0) -> 2078 | C10: =IFERROR(__xludf.DUMMYFUNCTION("""COMPUTED_VALUE"""),151524.0) -> 151524 | D10: =C10/B10 -> 72.918191
A11: =IFERROR(__xludf.DUMMYFUNCTION("""COMPUTED_VALUE"""),"Mini") -> Mini | B11: =IFERROR(__xludf.DUMMYFUNCTION("""COMPUTED_VALUE"""),944.0) -> 944 | C11: =IFERROR(__xludf.DUMMYFUNCTION("""COMPUTED_VALUE"""),43110.0) -> 43110 | D11: =C11/B11 -> 45.667373
A12: =IFERROR(__xludf.DUMMYFUNCTION("""COMPUTED_VALUE"""),"#N/A") -> #N/A | B12: =IFERROR(__xludf.DUMMYFUNCTION("""COMPUTED_VALUE"""),1.0) -> 1
A20: Key Findings:
A21: This report shows the number of customers, total revenue, and average revenue per customer for each subscription plan. We can see that the Residential plan generates the highest total revenue, while the Business plan has the highest average revenue per customer. This indicates that the Residential plan is the main revenue driver due to its large customer base, while Business customers generate more revenue individually.

Sheet Task #7
A1: TASK 07 — DISCOUNT EFFECTIVENESS
A3: Business Question:
A4: Are large discounts beneficial for the business?
A5: The marketing team wants to understand whether larger discounts generate enough additional revenue through customer volume to compensate for lower revenue per customer.
A7: Discount_category | B7: Customers | D7: Total Revenue | E7: Avg Revenue/Customer | F7: Revenue Share %
A8: =IFERROR(__xludf.DUMMYFUNCTION("QUERY(RawData!Q2:Q10002,""SELECT Q, COUNT(Q) GROUP BY Q ORDER BY COUNT(Q) DESC"",0)"),"") | B8: =IFERROR(__xludf.DUMMYFUNCTION("""COMPUTED_VALUE"""),"count ") -> count | C8: =IFERROR(__xludf.DUMMYFUNCTION("QUERY(RawData!O2:Q10002,""SELECT Q, SUM(O) GROUP BY Q ORDER BY SUM(O) DESC"",0)"),"") | D8: =IFERROR(__xludf.DUMMYFUNCTION("""COMPUTED_VALUE"""),"sum ") -> sum
A9: =IFERROR(__xludf.DUMMYFUNCTION("""COMPUTED_VALUE"""),"Large discount") -> Large discount | B9: =IFERROR(__xludf.DUMMYFUNCTION("""COMPUTED_VALUE"""),5000.0) -> 5000 | C9: =IFERROR(__xludf.DUMMYFUNCTION("""COMPUTED_VALUE"""),"Large discount") -> Large discount | D9: =IFERROR(__xludf.DUMMYFUNCTION("""COMPUTED_VALUE"""),504209.0) -> 504209 | E9: {=D9/_xlfn.XLOOKUP(A9,C$9:C$12,$B9:B$12)} -> 100.8418 | F9: =D9/(SUM($D$9:$D$11))*100 -> 46.688893 | G9: {=SORT({A9:A11,E9:E11},2,FALSE)} -> No discount | H9: 118.908
A10: =IFERROR(__xludf.DUMMYFUNCTION("""COMPUTED_VALUE"""),"No discount") -> No discount | B10: =IFERROR(__xludf.DUMMYFUNCTION("""COMPUTED_VALUE"""),2500.0) -> 2500 | C10: =IFERROR(__xludf.DUMMYFUNCTION("""COMPUTED_VALUE"""),"No discount") -> No discount | D10: =IFERROR(__xludf.DUMMYFUNCTION("""COMPUTED_VALUE"""),297270.0) -> 297270 | E10: {=D10/_xlfn.XLOOKUP(A10,C$9:C$12,$B9:B$12)} -> 118.908 | F10: =D10/(SUM($D$9:$D$11))*100 -> 27.526695 | G10: Small discount | H10: 111.3818
A11: =IFERROR(__xludf.DUMMYFUNCTION("""COMPUTED_VALUE"""),"Small discount") -> Small discount | B11: =IFERROR(__xludf.DUMMYFUNCTION("""COMPUTED_VALUE"""),2500.0) -> 2500 | C11: =IFERROR(__xludf.DUMMYFUNCTION("""COMPUTED_VALUE"""),"Small discount") -> Small discount | D11: =IFERROR(__xludf.DUMMYFUNCTION("""COMPUTED_VALUE"""),278454.5) -> 278454.5 | E11: {=D11/_xlfn.XLOOKUP(A11,C$9:C$12,$B9:B$12)} -> 111.3818 | F11: =D11/(SUM($D$9:$D$11))*100 -> 25.784412 | G11: Large discount | H11: 100.8418
A12: =IFERROR(__xludf.DUMMYFUNCTION("""COMPUTED_VALUE"""),"#N/A") -> #N/A | B12: =IFERROR(__xludf.DUMMYFUNCTION("""COMPUTED_VALUE"""),1.0) -> 1 | C12: =IFERROR(__xludf.DUMMYFUNCTION("""COMPUTED_VALUE"""),"#N/A") -> #N/A
A18: Key Findings:
A19: This report shows that a large discount does not guarantee higher average revenue per customer. On the contrary, customers without a discount generate the highest average revenue per customer. However, retention and churn data are not available, so we cannot determine the long-term impact of discounts on customer value.
A21: Business Recommendation:
A22: Consider reducing the size of discounts or testing smaller discounts, as large discounts are associated with lower average revenue per customer. Before making a final decision, analyze customer retention, churn, and upgrade rates to evaluate the long-term impact of discounts.
A24: Business Hypothesis:
A25: A 50% introductory discount on the Mini plan could attract new customers and encourage them to upgrade to higher-tier plans after the introductory period. To validate this hypothesis, we would need retention, churn, and upgrade data.

Sheet Task #8
A1: TASK 08 — CUSTOMER SEGMENTATION
A3: Business Case:
A4: Our customers are not all equally valuable. Can we segment them based on their monthly revenue and understand which customer groups generate the most value?
A7: Customer Segment | B7: Customers | C7: Total Revenue | D7: Average Revenue per Customer | E7: Revenue Share % | G7: Customer Segment | H7: Plan Name | I7: Customers
A8: =IFERROR(__xludf.DUMMYFUNCTION("QUERY(RawData!O2:R10002,""SELECT R, COUNT(R), SUM(O) GROUP BY R ORDER BY COUNT(R) DESC"",0)"),"") | B8: =IFERROR(__xludf.DUMMYFUNCTION("""COMPUTED_VALUE"""),"count ") -> count | C8: =IFERROR(__xludf.DUMMYFUNCTION("""COMPUTED_VALUE"""),"sum ") -> sum | G8: =IFERROR(__xludf.DUMMYFUNCTION("QUERY(RawData!O2:R10002,""SELECT R, P, COUNT(R) GROUP BY P, R ORDER BY COUNT(R) DESC"",0)"),"") | H8: =IFERROR(__xludf.DUMMYFUNCTION("""COMPUTED_VALUE"""),"") | I8: =IFERROR(__xludf.DUMMYFUNCTION("""COMPUTED_VALUE"""),"count ") -> count
A9: =IFERROR(__xludf.DUMMYFUNCTION("""COMPUTED_VALUE"""),"Low Value") -> Low Value | B9: =IFERROR(__xludf.DUMMYFUNCTION("""COMPUTED_VALUE"""),4510.0) -> 4510 | C9: =IFERROR(__xludf.DUMMYFUNCTION("""COMPUTED_VALUE"""),337482.0) -> 337482 | D9: =C9/B9 -> 74.829712 | E9: =(C9/SUM($C$9:$C$11)*100) -> 31.250258 | G9: =IFERROR(__xludf.DUMMYFUNCTION("""COMPUTED_VALUE"""),"Medium Value") -> Medium Value | H9: =IFERROR(__xludf.DUMMYFUNCTION("""COMPUTED_VALUE"""),"Residential") -> Residential | I9: =IFERROR(__xludf.DUMMYFUNCTION("""COMPUTED_VALUE"""),4471.0) -> 4471
A10: =IFERROR(__xludf.DUMMYFUNCTION("""COMPUTED_VALUE"""),"Medium Value") -> Medium Value | B10: =IFERROR(__xludf.DUMMYFUNCTION("""COMPUTED_VALUE"""),4471.0) -> 4471 | C10: =IFERROR(__xludf.DUMMYFUNCTION("""COMPUTED_VALUE"""),509664.0) -> 509664 | D10: =C10/B10 -> 113.99329 | E10: =(C10/SUM($C$9:$C$11)*100) -> 47.194017 | G10: =IFERROR(__xludf.DUMMYFUNCTION("""COMPUTED_VALUE"""),"Low Value") -> Low Value | H10: =IFERROR(__xludf.DUMMYFUNCTION("""COMPUTED_VALUE"""),"Roam") -> Roam | I10: =IFERROR(__xludf.DUMMYFUNCTION("""COMPUTED_VALUE"""),2078.0) -> 2078
A11: =IFERROR(__xludf.DUMMYFUNCTION("""COMPUTED_VALUE"""),"High Value") -> High Value | B11: =IFERROR(__xludf.DUMMYFUNCTION("""COMPUTED_VALUE"""),1019.0) -> 1019 | C11: =IFERROR(__xludf.DUMMYFUNCTION("""COMPUTED_VALUE"""),232787.5) -> 232787.5 | D11: =C11/B11 -> 228.44701 | E11: =(C11/SUM($C$9:$C$11)*100) -> 21.555725 | G11: =IFERROR(__xludf.DUMMYFUNCTION("""COMPUTED_VALUE"""),"Low Value") -> Low Value | H11: =IFERROR(__xludf.DUMMYFUNCTION("""COMPUTED_VALUE"""),"Residential") -> Residential | I11: =IFERROR(__xludf.DUMMYFUNCTION("""COMPUTED_VALUE"""),1488.0) -> 1488
A12: =IFERROR(__xludf.DUMMYFUNCTION("""COMPUTED_VALUE"""),"#N/A") -> #N/A | B12: =IFERROR(__xludf.DUMMYFUNCTION("""COMPUTED_VALUE"""),1.0) -> 1 | G12: =IFERROR(__xludf.DUMMYFUNCTION("""COMPUTED_VALUE"""),"High Value") -> High Value | H12: =IFERROR(__xludf.DUMMYFUNCTION("""COMPUTED_VALUE"""),"Business") -> Business | I12: =IFERROR(__xludf.DUMMYFUNCTION("""COMPUTED_VALUE"""),1019.0) -> 1019
G13: =IFERROR(__xludf.DUMMYFUNCTION("""COMPUTED_VALUE"""),"Low Value") -> Low Value | H13: =IFERROR(__xludf.DUMMYFUNCTION("""COMPUTED_VALUE"""),"Mini") -> Mini | I13: =IFERROR(__xludf.DUMMYFUNCTION("""COMPUTED_VALUE"""),944.0) -> 944
G14: =IFERROR(__xludf.DUMMYFUNCTION("""COMPUTED_VALUE"""),"#N/A") -> #N/A | H14: =IFERROR(__xludf.DUMMYFUNCTION("""COMPUTED_VALUE"""),"#N/A") -> #N/A | I14: =IFERROR(__xludf.DUMMYFUNCTION("""COMPUTED_VALUE"""),1.0) -> 1
A18: Key Findings:
A19: The report shows differences between customer segments. We can see that High Value customers account for only 10% of the total customer base but generate 21.5% of total revenue. This indicates that High Value customers are disproportionately important to the business. Customer value does not always correspond directly to the subscription plan, as discounts can move customers into a different value segment.

Sheet Task #9
A1: TASK 09 — COUNTRY × CUSTOMER VALUE
A3: Business Case:
A4: Which countries have the most valuable customers?
A7: Country | B7: Customer segment | C7: Customers | D7: Revenue | P7: Country | Q7: Segment | R7: Customers | T7: Country | U7: Low value | V7: Medium value | W7: High value | Y7: Country | Z7: Low value | AA7: Medium value | AB7: High value
A8: =IFERROR(__xludf.DUMMYFUNCTION("QUERY(RawData!E2:R10002,""SELECT E, R, COUNT(R), SUM(O) GROUP BY E, R"",0)"),"") | B8: =IFERROR(__xludf.DUMMYFUNCTION("""COMPUTED_VALUE"""),"") | C8: =IFERROR(__xludf.DUMMYFUNCTION("""COMPUTED_VALUE"""),"count ") -> count | D8: =IFERROR(__xludf.DUMMYFUNCTION("""COMPUTED_VALUE"""),"sum ") -> sum | F8: Country | G8: Customers | H8: Total revenue | I8: Avg revenue/Customer | J8: High value customers | K8: High value customer share | M8: Country | N8: Avg revenue/Customer | P8: =IFERROR(__xludf.DUMMYFUNCTION("QUERY(RawData!E2:R10002,""SELECT E, R, COUNT(R) GROUP BY E, R"",0)"),"") | Q8: =IFERROR(__xludf.DUMMYFUNCTION("""COMPUTED_VALUE"""),"") | R8: =IFERROR(__xludf.DUMMYFUNCTION("""COMPUTED_VALUE"""),"count ") -> count | T8: {=UNIQUE(P9:P997)} -> Australia | U8: =SUMIFS($R$8:$R997,$P$8:$P997,$T8,$Q$8:$Q997,U$7) -> 452 | V8: =SUMIFS($R$8:$R997,$P$8:$P997,$T8,$Q$8:$Q997,V$7) -> 480 | W8: =SUMIFS($R$8:$R997,$P$8:$P997,$T8,$Q$8:$Q997,W$7) -> 98 | Y8: {=UNIQUE(P9:P997)} -> Australia | Z8: =U8/SUM(U8:W8) -> 0.43883495 | AA8: =V8/SUM(U8:W8) -> 0.46601942 | AB8: =W8/SUM(U8:W8) -> 0.095145631
A9: =IFERROR(__xludf.DUMMYFUNCTION("""COMPUTED_VALUE"""),"Australia") -> Australia | B9: =IFERROR(__xludf.DUMMYFUNCTION("""COMPUTED_VALUE"""),"High Value") -> High Value | C9: =IFERROR(__xludf.DUMMYFUNCTION("""COMPUTED_VALUE"""),98.0) -> 98 | D9: =IFERROR(__xludf.DUMMYFUNCTION("""COMPUTED_VALUE"""),22287.5) -> 22287.5 | F9: {=UNIQUE(A9:A997)} -> Australia | G9: =SUMIF($A$9:$A997,F9,$C$9:$C997) -> 1030 | H9: =SUMIF($A$9:$A997,F9,$D$9:$D997) -> 111119.5 | I9: =H9/G9 -> 107.88301 | J9: =SUMIFS($C$9:$C997,$A$9:$A997,F9,$B$9:$B997,"High Value") -> 98 | K9: =(J9/G9)*100 -> 9.5145631 | M9: {=SORT({F9:F18,I9:I18},2,FALSE)} -> Japan | N9: 109.97945 | P9: =IFERROR(__xludf.DUMMYFUNCTION("""COMPUTED_VALUE"""),"Australia") -> Australia | Q9: =IFERROR(__xludf.DUMMYFUNCTION("""COMPUTED_VALUE"""),"High Value") -> High Value | R9: =IFERROR(__xludf.DUMMYFUNCTION("""COMPUTED_VALUE"""),98.0) -> 98 | T9: Brazil | U9: =SUMIFS($R$8:$R997,$P$8:$P997,$T9,$Q$8:$Q997,U$7) -> 471 | V9: =SUMIFS($R$8:$R997,$P$8:$P997,$T9,$Q$8:$Q997,V$7) -> 433 | W9: =SUMIFS($R$8:$R997,$P$8:$P997,$T9,$Q$8:$Q997,W$7) -> 92 | Y9: Brazil | Z9: =U9/SUM(U9:W9) -> 0.47289157 | AA9: =V9/SUM(U9:W9) -> 0.43473896 | AB9: =W9/SUM(U9:W9) -> 0.092369478
A10: =IFERROR(__xludf.DUMMYFUNCTION("""COMPUTED_VALUE"""),"Australia") -> Australia | B10: =IFERROR(__xludf.DUMMYFUNCTION("""COMPUTED_VALUE"""),"Low Value") -> Low Value | C10: =IFERROR(__xludf.DUMMYFUNCTION("""COMPUTED_VALUE"""),452.0) -> 452 | D10: =IFERROR(__xludf.DUMMYFUNCTION("""COMPUTED_VALUE"""),34400.0) -> 34400 | F10: Brazil | G10: =SUMIF($A$9:$A998,F10,$C$9:$C998) -> 996 | H10: =SUMIF($A$9:$A998,F10,$D$9:$D998) -> 105391 | I10: =H10/G10 -> 105.81426 | J10: =SUMIFS($C$9:$C998,$A$9:$A998,F10,$B$9:$B998,"High Value") -> 92 | K10: =(J10/G10)*100 -> 9.2369478 | M10: Spain | N10: 109.70854 | P10: =IFERROR(__xludf.DUMMYFUNCTION("""COMPUTED_VALUE"""),"Australia") -> Australia | Q10: =IFERROR(__xludf.DUMMYFUNCTION("""COMPUTED_VALUE"""),"Low Value") -> Low Value | R10: =IFERROR(__xludf.DUMMYFUNCTION("""COMPUTED_VALUE"""),452.0) -> 452 | T10: Canada | U10: =SUMIFS($R$8:$R997,$P$8:$P997,$T10,$Q$8:$Q997,U$7) -> 438 | V10: =SUMIFS($R$8:$R997,$P$8:$P997,$T10,$Q$8:$Q997,V$7) -> 456 | W10: =SUMIFS($R$8:$R997,$P$8:$P997,$T10,$Q$8:$Q997,W$7) -> 103 | Y10: Canada | Z10: =U10/SUM(U10:W10) -> 0.43931795 | AA10: =V10/SUM(U10:W10) -> 0.45737212 | AB10: =W10/SUM(U10:W10) -> 0.10330993
A11: =IFERROR(__xludf.DUMMYFUNCTION("""COMPUTED_VALUE"""),"Australia") -> Australia | B11: =IFERROR(__xludf.DUMMYFUNCTION("""COMPUTED_VALUE"""),"Medium Value") -> Medium Value | C11: =IFERROR(__xludf.DUMMYFUNCTION("""COMPUTED_VALUE"""),480.0) -> 480 | D11: =IFERROR(__xludf.DUMMYFUNCTION("""COMPUTED_VALUE"""),54432.0) -> 54432 | F11: Canada | G11: =SUMIF($A$9:$A999,F11,$C$9:$C999) -> 997 | H11: =SUMIF($A$9:$A999,F11,$D$9:$D999) -> 109096.5 | I11: =H11/G11 -> 109.42477 | J11: =SUMIFS($C$9:$C999,$A$9:$A999,F11,$B$9:$B999,"High Value") -> 103 | K11: =(J11/G11)*100 -> 10.330993 | M11: Canada | N11: 109.42477 | P11: =IFERROR(__xludf.DUMMYFUNCTION("""COMPUTED_VALUE"""),"Australia") -> Australia | Q11: =IFERROR(__xludf.DUMMYFUNCTION("""COMPUTED_VALUE"""),"Medium Value") -> Medium Value | R11: =IFERROR(__xludf.DUMMYFUNCTION("""COMPUTED_VALUE"""),480.0) -> 480 | T11: France | U11: =SUMIFS($R$8:$R997,$P$8:$P997,$T11,$Q$8:$Q997,U$7) -> 449 | V11: =SUMIFS($R$8:$R997,$P$8:$P997,$T11,$Q$8:$Q997,V$7) -> 440 | W11: =SUMIFS($R$8:$R997,$P$8:$P997,$T11,$Q$8:$Q997,W$7) -> 107 | Y11: France | Z11: =U11/SUM(U11:W11) -> 0.45080321 | AA11: =V11/SUM(U11:W11) -> 0.44176707 | AB11: =W11/SUM(U11:W11) -> 0.10742972
A12: =IFERROR(__xludf.DUMMYFUNCTION("""COMPUTED_VALUE"""),"Brazil") -> Brazil | B12: =IFERROR(__xludf.DUMMYFUNCTION("""COMPUTED_VALUE"""),"High Value") -> High Value | C12: =IFERROR(__xludf.DUMMYFUNCTION("""COMPUTED_VALUE"""),92.0) -> 92 | D12: =IFERROR(__xludf.DUMMYFUNCTION("""COMPUTED_VALUE"""),20937.5) -> 20937.5 | F12: France | G12: =SUMIF($A$9:$A1000,F12,$C$9:$C1000) -> 996 | H12: =SUMIF($A$9:$A1000,F12,$D$9:$D1000) -> 107789 | I12: =H12/G12 -> 108.22189 | J12: =SUMIFS($C$9:$C1000,$A$9:$A1000,F12,$B$9:$B1000,"High Value") -> 107 | K12: =(J12/G12)*100 -> 10.742972 | M12: United States | N12: 109.24686 | P12: =IFERROR(__xludf.DUMMYFUNCTION("""COMPUTED_VALUE"""),"Brazil") -> Brazil | Q12: =IFERROR(__xludf.DUMMYFUNCTION("""COMPUTED_VALUE"""),"High Value") -> High Value | R12: =IFERROR(__xludf.DUMMYFUNCTION("""COMPUTED_VALUE"""),92.0) -> 92 | T12: Germany | U12: =SUMIFS($R$8:$R997,$P$8:$P997,$T12,$Q$8:$Q997,U$7) -> 478 | V12: =SUMIFS($R$8:$R997,$P$8:$P997,$T12,$Q$8:$Q997,V$7) -> 468 | W12: =SUMIFS($R$8:$R997,$P$8:$P997,$T12,$Q$8:$Q997,W$7) -> 81 | Y12: Germany | Z12: =U12/SUM(U12:W12) -> 0.4654333 | AA12: =V12/SUM(U12:W12) -> 0.4556962 | AB12: =W12/SUM(U12:W12) -> 0.078870497
A13: =IFERROR(__xludf.DUMMYFUNCTION("""COMPUTED_VALUE"""),"Brazil") -> Brazil | B13: =IFERROR(__xludf.DUMMYFUNCTION("""COMPUTED_VALUE"""),"Low Value") -> Low Value | C13: =IFERROR(__xludf.DUMMYFUNCTION("""COMPUTED_VALUE"""),471.0) -> 471 | D13: =IFERROR(__xludf.DUMMYFUNCTION("""COMPUTED_VALUE"""),35079.5) -> 35079.5 | F13: Germany | G13: =SUMIF($A$9:$A1001,F13,$C$9:$C1001) -> 1027 | H13: =SUMIF($A$9:$A1001,F13,$D$9:$D1001) -> 108088 | I13: =H13/G13 -> 105.24635 | J13: =SUMIFS($C$9:$C1001,$A$9:$A1001,F13,$B$9:$B1001,"High Value") -> 81 | K13: =(J13/G13)*100 -> 7.8870497 | M13: France | N13: 108.22189 | P13: =IFERROR(__xludf.DUMMYFUNCTION("""COMPUTED_VALUE"""),"Brazil") -> Brazil | Q13: =IFERROR(__xludf.DUMMYFUNCTION("""COMPUTED_VALUE"""),"Low Value") -> Low Value | R13: =IFERROR(__xludf.DUMMYFUNCTION("""COMPUTED_VALUE"""),471.0) -> 471 | T13: Japan | U13: =SUMIFS($R$8:$R997,$P$8:$P997,$T13,$Q$8:$Q997,U$7) -> 426 | V13: =SUMIFS($R$8:$R997,$P$8:$P997,$T13,$Q$8:$Q997,V$7) -> 428 | W13: =SUMIFS($R$8:$R997,$P$8:$P997,$T13,$Q$8:$Q997,W$7) -> 119 | Y13: Japan | Z13: =U13/SUM(U13:W13) -> 0.43782117 | AA13: =V13/SUM(U13:W13) -> 0.43987667 | AB13: =W13/SUM(U13:W13) -> 0.12230216
A14: =IFERROR(__xludf.DUMMYFUNCTION("""COMPUTED_VALUE"""),"Brazil") -> Brazil | B14: =IFERROR(__xludf.DUMMYFUNCTION("""COMPUTED_VALUE"""),"Medium Value") -> Medium Value | C14: =IFERROR(__xludf.DUMMYFUNCTION("""COMPUTED_VALUE"""),433.0) -> 433 | D14: =IFERROR(__xludf.DUMMYFUNCTION("""COMPUTED_VALUE"""),49374.0) -> 49374 | F14: Japan | G14: =SUMIF($A$9:$A1002,F14,$C$9:$C1002) -> 973 | H14: =SUMIF($A$9:$A1002,F14,$D$9:$D1002) -> 107010 | I14: =H14/G14 -> 109.97944 | J14: =SUMIFS($C$9:$C1002,$A$9:$A1002,F14,$B$9:$B1002,"High Value") -> 119 | K14: =(J14/G14)*100 -> 12.230216 | M14: Ukraine | N14: 108.15795 | P14: =IFERROR(__xludf.DUMMYFUNCTION("""COMPUTED_VALUE"""),"Brazil") -> Brazil | Q14: =IFERROR(__xludf.DUMMYFUNCTION("""COMPUTED_VALUE"""),"Medium Value") -> Medium Value | R14: =IFERROR(__xludf.DUMMYFUNCTION("""COMPUTED_VALUE"""),433.0) -> 433 | T14: Spain | U14: =SUMIFS($R$8:$R997,$P$8:$P997,$T14,$Q$8:$Q997,U$7) -> 442 | V14: =SUMIFS($R$8:$R997,$P$8:$P997,$T14,$Q$8:$Q997,V$7) -> 464 | W14: =SUMIFS($R$8:$R997,$P$8:$P997,$T14,$Q$8:$Q997,W$7) -> 113 | Y14: Spain | Z14: =U14/SUM(U14:W14) -> 0.43375859 | AA14: =V14/SUM(U14:W14) -> 0.45534838 | AB14: =W14/SUM(U14:W14) -> 0.11089303
A15: =IFERROR(__xludf.DUMMYFUNCTION("""COMPUTED_VALUE"""),"Canada") -> Canada | B15: =IFERROR(__xludf.DUMMYFUNCTION("""COMPUTED_VALUE"""),"High Value") -> High Value | C15: =IFERROR(__xludf.DUMMYFUNCTION("""COMPUTED_VALUE"""),103.0) -> 103 | D15: =IFERROR(__xludf.DUMMYFUNCTION("""COMPUTED_VALUE"""),23437.5) -> 23437.5 | F15: Spain | G15: =SUMIF($A$9:$A1003,F15,$C$9:$C1003) -> 1019 | H15: =SUMIF($A$9:$A1003,F15,$D$9:$D1003) -> 111793 | I15: =H15/G15 -> 109.70854 | J15: =SUMIFS($C$9:$C1003,$A$9:$A1003,F15,$B$9:$B1003,"High Value") -> 113 | K15: =(J15/G15)*100 -> 11.089303 | M15: Australia | N15: 107.88301 | P15: =IFERROR(__xludf.DUMMYFUNCTION("""COMPUTED_VALUE"""),"Canada") -> Canada | Q15: =IFERROR(__xludf.DUMMYFUNCTION("""COMPUTED_VALUE"""),"High Value") -> High Value | R15: =IFERROR(__xludf.DUMMYFUNCTION("""COMPUTED_VALUE"""),103.0) -> 103 | T15: Ukraine | U15: =SUMIFS($R$8:$R997,$P$8:$P997,$T15,$Q$8:$Q997,U$7) -> 460 | V15: =SUMIFS($R$8:$R997,$P$8:$P997,$T15,$Q$8:$Q997,V$7) -> 465 | W15: =SUMIFS($R$8:$R997,$P$8:$P997,$T15,$Q$8:$Q997,W$7) -> 106 | Y15: Ukraine | Z15: =U15/SUM(U15:W15) -> 0.44616877 | AA15: =V15/SUM(U15:W15) -> 0.45101843 | AB15: =W15/SUM(U15:W15) -> 0.1028128
A16: =IFERROR(__xludf.DUMMYFUNCTION("""COMPUTED_VALUE"""),"Canada") -> Canada | B16: =IFERROR(__xludf.DUMMYFUNCTION("""COMPUTED_VALUE"""),"Low Value") -> Low Value | C16: =IFERROR(__xludf.DUMMYFUNCTION("""COMPUTED_VALUE"""),438.0) -> 438 | D16: =IFERROR(__xludf.DUMMYFUNCTION("""COMPUTED_VALUE"""),33501.0) -> 33501 | F16: Ukraine | G16: =SUMIF($A$9:$A1004,F16,$C$9:$C1004) -> 1032 | H16: =SUMIF($A$9:$A1004,F16,$D$9:$D1004) -> 111619 | I16: =H16/G16 -> 108.15795 | J16: =SUMIFS($C$9:$C1004,$A$9:$A1004,F16,$B$9:$B1004,"High Value") -> 106 | K16: =(J16/G16)*100 -> 10.271318 | M16: United Kingdom | N16: 106.24974 | P16: =IFERROR(__xludf.DUMMYFUNCTION("""COMPUTED_VALUE"""),"Canada") -> Canada | Q16: =IFERROR(__xludf.DUMMYFUNCTION("""COMPUTED_VALUE"""),"Low Value") -> Low Value | R16: =IFERROR(__xludf.DUMMYFUNCTION("""COMPUTED_VALUE"""),438.0) -> 438 | T16: United Kingdom | U16: =SUMIFS($R$8:$R997,$P$8:$P997,$T16,$Q$8:$Q997,U$7) -> 468 | V16: =SUMIFS($R$8:$R997,$P$8:$P997,$T16,$Q$8:$Q997,V$7) -> 415 | W16: =SUMIFS($R$8:$R997,$P$8:$P997,$T16,$Q$8:$Q997,W$7) -> 94 | Y16: United Kingdom | Z16: =U16/SUM(U16:W16) -> 0.4790174 | AA16: =V16/SUM(U16:W16) -> 0.4247697 | AB16: =W16/SUM(U16:W16) -> 0.096212897
A17: =IFERROR(__xludf.DUMMYFUNCTION("""COMPUTED_VALUE"""),"Canada") -> Canada | B17: =IFERROR(__xludf.DUMMYFUNCTION("""COMPUTED_VALUE"""),"Medium Value") -> Medium Value | C17: =IFERROR(__xludf.DUMMYFUNCTION("""COMPUTED_VALUE"""),456.0) -> 456 | D17: =IFERROR(__xludf.DUMMYFUNCTION("""COMPUTED_VALUE"""),52158.0) -> 52158 | F17: United Kingdom | G17: =SUMIF($A$9:$A1005,F17,$C$9:$C1005) -> 977 | H17: =SUMIF($A$9:$A1005,F17,$D$9:$D1005) -> 103806 | I17: =H17/G17 -> 106.24974 | J17: =SUMIFS($C$9:$C1005,$A$9:$A1005,F17,$B$9:$B1005,"High Value") -> 94 | K17: =(J17/G17)*100 -> 9.6212897 | M17: Brazil | N17: 105.81426 | P17: =IFERROR(__xludf.DUMMYFUNCTION("""COMPUTED_VALUE"""),"Canada") -> Canada | Q17: =IFERROR(__xludf.DUMMYFUNCTION("""COMPUTED_VALUE"""),"Medium Value") -> Medium Value | R17: =IFERROR(__xludf.DUMMYFUNCTION("""COMPUTED_VALUE"""),456.0) -> 456 | T17: United States | U17: =SUMIFS($R$8:$R997,$P$8:$P997,$T17,$Q$8:$Q997,U$7) -> 426 | V17: =SUMIFS($R$8:$R997,$P$8:$P997,$T17,$Q$8:$Q997,V$7) -> 422 | W17: =SUMIFS($R$8:$R997,$P$8:$P997,$T17,$Q$8:$Q997,W$7) -> 106 | Y17: United States | Z17: =U17/SUM(U17:W17) -> 0.44654088 | AA17: =V17/SUM(U17:W17) -> 0.44234801 | AB17: =W17/SUM(U17:W17) -> 0.11111111
A18: =IFERROR(__xludf.DUMMYFUNCTION("""COMPUTED_VALUE"""),"France") -> France | B18: =IFERROR(__xludf.DUMMYFUNCTION("""COMPUTED_VALUE"""),"High Value") -> High Value | C18: =IFERROR(__xludf.DUMMYFUNCTION("""COMPUTED_VALUE"""),107.0) -> 107 | D18: =IFERROR(__xludf.DUMMYFUNCTION("""COMPUTED_VALUE"""),24362.5) -> 24362.5 | F18: United States | G18: =SUMIF($A$9:$A1006,F18,$C$9:$C1006) -> 954 | H18: =SUMIF($A$9:$A1006,F18,$D$9:$D1006) -> 104221.5 | I18: =H18/G18 -> 109.24686 | J18: =SUMIFS($C$9:$C1006,$A$9:$A1006,F18,$B$9:$B1006,"High Value") -> 106 | K18: =(J18/G18)*100 -> 11.111111 | M18: Germany | N18: 105.24635 | P18: =IFERROR(__xludf.DUMMYFUNCTION("""COMPUTED_VALUE"""),"France") -> France | Q18: =IFERROR(__xludf.DUMMYFUNCTION("""COMPUTED_VALUE"""),"High Value") -> High Value | R18: =IFERROR(__xludf.DUMMYFUNCTION("""COMPUTED_VALUE"""),107.0) -> 107
A19: =IFERROR(__xludf.DUMMYFUNCTION("""COMPUTED_VALUE"""),"France") -> France | B19: =IFERROR(__xludf.DUMMYFUNCTION("""COMPUTED_VALUE"""),"Low Value") -> Low Value | C19: =IFERROR(__xludf.DUMMYFUNCTION("""COMPUTED_VALUE"""),449.0) -> 449 | D19: =IFERROR(__xludf.DUMMYFUNCTION("""COMPUTED_VALUE"""),33218.5) -> 33218.5 | P19: =IFERROR(__xludf.DUMMYFUNCTION("""COMPUTED_VALUE"""),"France") -> France | Q19: =IFERROR(__xludf.DUMMYFUNCTION("""COMPUTED_VALUE"""),"Low Value") -> Low Value | R19: =IFERROR(__xludf.DUMMYFUNCTION("""COMPUTED_VALUE"""),449.0) -> 449
A20: =IFERROR(__xludf.DUMMYFUNCTION("""COMPUTED_VALUE"""),"France") -> France | B20: =IFERROR(__xludf.DUMMYFUNCTION("""COMPUTED_VALUE"""),"Medium Value") -> Medium Value | C20: =IFERROR(__xludf.DUMMYFUNCTION("""COMPUTED_VALUE"""),440.0) -> 440 | D20: =IFERROR(__xludf.DUMMYFUNCTION("""COMPUTED_VALUE"""),50208.0) -> 50208 | P20: =IFERROR(__xludf.DUMMYFUNCTION("""COMPUTED_VALUE"""),"France") -> France | Q20: =IFERROR(__xludf.DUMMYFUNCTION("""COMPUTED_VALUE"""),"Medium Value") -> Medium Value | R20: =IFERROR(__xludf.DUMMYFUNCTION("""COMPUTED_VALUE"""),440.0) -> 440
A21: =IFERROR(__xludf.DUMMYFUNCTION("""COMPUTED_VALUE"""),"Germany") -> Germany | B21: =IFERROR(__xludf.DUMMYFUNCTION("""COMPUTED_VALUE"""),"High Value") -> High Value | C21: =IFERROR(__xludf.DUMMYFUNCTION("""COMPUTED_VALUE"""),81.0) -> 81 | D21: =IFERROR(__xludf.DUMMYFUNCTION("""COMPUTED_VALUE"""),18550.0) -> 18550 | P21: =IFERROR(__xludf.DUMMYFUNCTION("""COMPUTED_VALUE"""),"Germany") -> Germany | Q21: =IFERROR(__xludf.DUMMYFUNCTION("""COMPUTED_VALUE"""),"High Value") -> High Value | R21: =IFERROR(__xludf.DUMMYFUNCTION("""COMPUTED_VALUE"""),81.0) -> 81
